Workbook

Sheet Status & Missing
B2: Data Status — What's Loaded and What's Still Missing
B4: OPTIMAL AND CLASS A LTD · Amazon.co.uk · 13 monthly Summary PDFs + 13 Transaction CSVs (Jun 2025 – Jun 2026)
B6: ✓ Loaded, reconciled and now enriched with transaction-level data
B7: • All 13 months reconcile to the penny vs Amazon's stated Income & Expenses totals (see check rows on the P&L tab).
B8: • Transaction CSVs added UNITS SOLD (8,503 net units TTM) and average selling price (£12.33) — COGS is now driven by real units × landed cost, not a guess.
B9: • SKU-level revenue extracted → see the 'SKU Concentration' tab (22 SKUs across ~3 product families).
B10: • Storage/inbound fees confirmed month-by-month from the 'FBA Inventory Fee' transaction lines.
B11: • Business Reports added TRAFFIC & CONVERSION → see the 'Traffic & Conversion' tab: TTM 56,053 sessions, 15.4% conversion, ~29 child ASINs. Buy Box ~99% for most of the year.
B13: ⚠ VAT — the transaction data raises a real question
B14: • 98.4% of sales are UK domestic (tax-collection-model blank) and Amazon collected £0 VAT on them. Only 1.6% (EU/NI 'MarketplaceFacilitator' orders) had VAT handled by Amazon.
B15: • TTM turnover ~£107k is above the £90k registration threshold, yet no VAT is being collected on UK sales. Either the seller is VAT-registered and self-accounts (so ~£17.5k/yr output VAT is a real cost, prices being VAT-inclusive), OR they are not registered despite being over the threshold (a compliance liability that can pass to a buyer).
B16: • ACTION: get the VAT registration number, the VAT scheme (standard/flat-rate), and the last 4 VAT returns. This single point can swing the whole valuation.
... B32: • Seller says no suspensions/violations and offers live verification at acquisition — do that.

Sheet P&L (from PDFs)
A1: MONTHLY P&L — settlement data + units from transaction files (£)
A2: Costs negative. TTM = Jul-25 to Jun-26. Blue = actual data, black = formula, yellow = assumption to replace.
A3: Line item | B3: Jun-25 | C3: Jul-25 | D3: Aug-25 | E3: Sep-25 | F3: Oct-25 | G3: Nov-25 | H3: Dec-25 | I3: Jan-26 | J3: Feb-26 | K3: Mar-26 | L3: Apr-26 | M3: May-26 | N3: Jun-26 | O3: TTM | P3: TTM avg/mo
A4: REVENUE
A5: Product Sales (FBA + seller-fulfilled) | B5: 6621.98 | C5: 7292.55 | D5: 5945.62 | E5: 9358.88 | F5: 8112.06 | G5: 14133.11 | H5: 22261.78 | I5: 6844.32 | J5: 5540.05 | K5: 7593.8 | L5: 7048.16 | M5: 6570.32 | N5: 6135.29 | O5: =SUM(C5:N5) -> 106835.94 | P5: =O5/12 -> 8902.995
A6: Other Income (postage, inventory, gift-wrap) | B6: 162.36 | C6: 239.09 | D6: 250.83 | E6: 289.28 | F6: 202.79 | G6: 329.65 | H6: 525.5 | I6: 352.53 | J6: 226.53 | K6: 251.49 | L6: 244.56 | M6: 231.45 | N6: 165.76 | O6: =SUM(C6:N6) -> 3309.46 | P6: =O6/12 -> 275.78833
A7: less: Promotional Rebates (net) | B7: -241.64 | C7: -87.65 | D7: -190.32 | E7: -114.8 | F7: -68.39 | G7: -133.72 | H7: -307.44 | I7: -81.22 | J7: -63.75 | K7: -95.15 | L7: -164.93 | M7: -193.27 | N7: -98.04 | O7: =SUM(C7:N7) -> -1598.68 | P7: =O7/12 -> -133.22333
A8: less: Returns & Refunds (incl. delivery credits) | B8: -29.47 | C8: -106.6 | D8: -105.96 | E8: -136.55 | F8: -162.56 | G8: -206.23 | H8: -349.55 | I8: -261.19 | J8: -117.05 | K8: -172.99 | L8: -135.34 | M8: -43.84 | N8: -59.2 | O8: =SUM(C8:N8) -> -1857.06 | P8: =O8/12 -> -154.755
A9: Net Sales | B9: =SUM(B5:B8) -> 6513.23 | C9: =SUM(C5:C8) -> 7337.39 | D9: =SUM(D5:D8) -> 5900.17 | E9: =SUM(E5:E8) -> 9396.81 | F9: =SUM(F5:F8) -> 8083.9 | G9: =SUM(G5:G8) -> 14122.81 | H9: =SUM(H5:H8) -> 22130.29 | I9: =SUM(I5:I8) -> 6854.44 | ... N9: =SUM(N5:N8) -> 6143.81 | O9: =SUM(C9:N9) -> 106689.66 | P9: =O9/12 -> 8890.805
A10: check: Amazon 'Income' total (PDF) | B10: 6513.23 | C10: 7337.39 | D10: 5900.17 | E10: 9396.81 | F10: 8083.9 | G10: 14122.81 | H10: 22130.29 | I10: 6854.44 | J10: 5585.78 | K10: 7577.15 | L10: 6992.45 | M10: 6564.66 | N10: 6143.81 | O10: =SUM(C10:N10) -> 106689.66
A11: check: Difference (0) | B11: =B9-B10 -> 0 | C11: =C9-C10 -> 0 | D11: =D9-D10 -> 0 | E11: =E9-E10 -> 0 | F11: =F9-F10 -> 0 | G11: =G9-G10 -> 0 | H11: =H9-H10 -> 0 | I11: =I9-I10 -> 0 | ... O11: =O9-O10 -> 0
A13: AMAZON FEES (VAT-inclusive; referral & FBA split into net + VAT @20%)
A14: Referral / Selling Fees (ex-VAT) | B14: -652.36 | C14: -422.38 | D14: -105.31 | E14: -816.83 | F14: -247.56 | G14: -1337.03 | H14: -2546.86 | I14: 27.46 | J14: -109.4 | K14: -927.68 | L14: -857.47 | M14: -929.08 | N14: -746.82 | O14: =SUM(C14:N14) -> -9018.96 | P14: =O14/12 -> -751.58
A15: Referral Fees — VAT @20% | B15: -130.47 | C15: -84.48 | D15: -21.06 | E15: -163.36 | F15: -49.51 | G15: -267.41 | H15: -509.37 | I15: 5.49 | J15: -21.88 | K15: -185.53 | L15: -171.49 | M15: -185.82 | N15: -149.36 | O15: =SUM(C15:N15) -> -1803.78 | P15: =O15/12 -> -150.315
A16: FBA Fulfilment Fees (ex-VAT) | B16: -1399.98 | C16: -1706.32 | D16: -1386.23 | E16: -1994.89 | F16: -1723.09 | G16: -2887.29 | H16: -3897.27 | I16: -1491.82 | J16: -1148.85 | K16: -1548.76 | L16: -1383.98 | M16: -1435.76 | N16: -1475.08 | O16: =SUM(C16:N16) -> -22079.34 | P16: =O16/12 -> -1839.945
A17: FBA Fulfilment Fees — VAT @20% | B17: -279.99 | C17: -341.26 | D17: -277.25 | E17: -398.98 | F17: -344.62 | G17: -577.46 | H17: -779.45 | I17: -298.36 | J17: -229.77 | K17: -309.75 | L17: -276.79 | M17: -287.15 | N17: -295.01 | O17: =SUM(C17:N17) -> -4415.85 | P17: =O17/12 -> -367.9875
A18: Storage & Inbound Fees (incl. VAT) | B18: -169.72 | C18: -101.55 | D18: -158.52 | E18: -88.89 | F18: -156.98 | G18: -200.53 | H18: -434.77 | I18: -401.56 | J18: -290.96 | K18: -265.61 | L18: -237.77 | M18: -41.8 | N18: 0 | O18: =SUM(C18:N18) -> -2378.94 | P18: =O18/12 -> -198.245
A19: Other Fees (incl. VAT) | B19: -181.33 | C19: -115.1 | D19: -65.67 | E19: -107.04 | F19: -208.84 | G19: -172.2 | H19: -194.8 | I19: -70.2 | J19: -150.37 | K19: -234.79 | L19: -206.4 | M19: -160.17 | N19: -130.54 | O19: =SUM(C19:N19) -> -1816.12 | P19: =O19/12 -> -151.34333
A20: Total Amazon Fees (incl. VAT, excl. ads) | B20: =SUM(B14:B19) -> -2813.85 | C20: =SUM(C14:C19) -> -2771.09 | D20: =SUM(D14:D19) -> -2014.04 | E20: =SUM(E14:E19) -> -3569.99 | F20: =SUM(F14:F19) -> -2730.6 | G20: =SUM(G14:G19) -> -5441.92 | H20: =SUM(H14:H19) -> -8362.52 | I20: =SUM(I14:I19) -> -2228.99 | ... N20: =SUM(N14:N19) -> -2796.81 | O20: =SUM(C20:N20) -> -41512.99 | P20: =O20/12 -> -3459.4158
A22: ADVERTISING / PPC (from 42 actual invoices; split net + VAT @20%)
A23: PPC / Advertising (ex-VAT) | B23: -507.6 | C23: -172.63 | D23: -1596.6 | E23: -1731.41 | F23: -1302.08 | G23: -1370.32 | H23: -2104.05 | I23: -1410.93 | J23: -701.01 | K23: -1448.55 | L23: -1316.6 | M23: -1113.7 | N23: -1283.71 | O23: =SUM(C23:N23) -> -15551.59 | P23: =O23/12 -> -1295.9658
A24: PPC / Advertising — VAT @20% | B24: -101.52 | C24: -34.53 | D24: -319.32 | E24: -346.28 | F24: -260.41 | G24: -274.06 | H24: -420.81 | I24: -282.19 | J24: -140.2 | K24: -289.71 | L24: -263.32 | M24: -222.74 | N24: -256.74 | O24: =SUM(C24:N24) -> -3110.31 | P24: =O24/12 -> -259.1925
A25: Total PPC (incl. VAT) | B25: =B23+B24 -> -609.12 | C25: =C23+C24 -> -207.16 | D25: =D23+D24 -> -1915.92 | E25: =E23+E24 -> -2077.69 | F25: =F23+F24 -> -1562.49 | G25: =G23+G24 -> -1644.38 | H25: =H23+H24 -> -2524.86 | I25: =I23+I24 -> -1693.12 | ... N25: =N23+N24 -> -1540.45 | O25: =SUM(C25:N25) -> -18661.9 | P25: =O25/12 -> -1555.1583
A26: check: Amazon 'Expenses' total (PDF) | B26: -3422.97 | C26: -2978.25 | D26: -3929.96 | E26: -5647.68 | F26: -4293.09 | G26: -7086.3 | H26: -10887.38 | I26: -3922.11 | J26: -2792.44 | K26: -5210.38 | L26: -4713.82 | M26: -4376.22 | N26: -4337.26 | O26: =SUM(C26:N26) -> -60174.89
A27: check: Difference (0) | B27: =(B20+B25)-B26 -> 0 | C27: =(C20+C25)-C26 -> 0 | D27: =(D20+D25)-D26 -> 0 | E27: =(E20+E25)-E26 -> 0 | F27: =(F20+F25)-F26 -> 0 | G27: =(G20+G25)-G26 -> 0 | H27: =(H20+H25)-H26 -> 0 | I27: =(I20+I25)-I26 -> 0 | ... O27: =(O20+O25)-O26 -> 0
A29: COGS, VAT & NET PROFIT
A30: Units Sold (net, from transaction files) | B30: 477 | C30: 672 | D30: 597 | E30: 776 | F30: 740 | G30: 1136 | H30: 1479 | I30: 580 | J30: 436 | K30: 571 | L30: 440 | M30: 464 | N30: 612 | O30: =SUM(C30:N30) -> 8503 | P30: =O30/12 -> 708.58333
A31: Avg Selling Price | B31: =IFERROR(B5/B30,0) -> 13.882558 | C31: =IFERROR(C5/C30,0) -> 10.852009 | D31: =IFERROR(D5/D30,0) -> 9.9591625 | E31: =IFERROR(E5/E30,0) -> 12.060412 | F31: =IFERROR(F5/F30,0) -> 10.962243 | G31: =IFERROR(G5/G30,0) -> 12.441118 | H31: =IFERROR(H5/H30,0) -> 15.051913 | I31: =IFERROR(I5/I30,0) -> 11.800552 | ... O31: =IFERROR(O5/O30,0) -> 12.5645 | P31: =O31 -> 12.5645
A32: COGS (DDP + import VAT incl.; per-SKU) | B32: =-'COGS Build'!C27 -> -2303.11 | C32: =-'COGS Build'!D27 -> -2247.32 | D32: =-'COGS Build'!E27 -> -1373.37 | E32: =-'COGS Build'!F27 -> -2465.23 | F32: =-'COGS Build'!G27 -> -1935.06 | G32: =-'COGS Build'!H27 -> -3804.58 | H32: =-'COGS Build'!I27 -> -4869.15 | I32: =-'COGS Build'!J27 -> -1690.84 | ... N32: =-'COGS Build'!O27 -> -1457.15 | O32: =SUM(C32:N32) -> -27290.42 | P32: =O32/12 -> -2274.2017
A33: Output VAT (business NOT VAT-registered -> £0) | B33: 0 | C33: 0 | D33: 0 | E33: 0 | F33: 0 | G33: 0 | H33: 0 | I33: 0 | J33: 0 | K33: 0 | L33: 0 | M33: 0 | N33: 0 | O33: =SUM(C33:N33) -> 0 | P33: =O33/12 -> 0
A34: Estimated Net Profit | B34: =B9+B20+B25+B32+B33 -> 787.15 | C34: =C9+C20+C25+C32+C33 -> 2111.82 | D34: =D9+D20+D25+D32+D33 -> 596.84 | E34: =E9+E20+E25+E32+E33 -> 1283.9 | F34: =F9+F20+F25+F32+F33 -> 1855.75 | G34: =G9+G20+G25+G32+G33 -> 3231.93 | H34: =H9+H20+H25+H32+H33 -> 6373.76 | I34: =I9+I20+I25+I32+I33 -> 1241.49 | ... N34: =N9+N20+N25+N32+N33 -> 349.4 | O34: =SUM(C34:N34) -> 19224.35 | P34: =O34/12 -> 1602.0292
A36: KEY METRICS
A37: TACoS % (PPC incl VAT / net sales) | B37: =IFERROR(-B25/B9,0) -> 0.093520419 | C37: =IFERROR(-C25/C9,0) -> 0.028233473 | D37: =IFERROR(-D25/D9,0) -> 0.32472285 | E37: =IFERROR(-E25/E9,0) -> 0.22110589 | F37: =IFERROR(-F25/F9,0) -> 0.19328418 | G37: =IFERROR(-G25/G9,0) -> 0.11643434 | H37: =IFERROR(-H25/H9,0) -> 0.11409069 | I37: =IFERROR(-I25/I9,0) -> 0.2470107 | ... O37: =IFERROR(-O25/O9,0) -> 0.17491761
A38: Refund rate % | B38: =IFERROR(-B8/B5,0) -> 0.0044503306 | C38: =IFERROR(-C8/C5,0) -> 0.014617658 | D38: =IFERROR(-D8/D5,0) -> 0.017821522 | E38: =IFERROR(-E8/E5,0) -> 0.014590421 | F38: =IFERROR(-F8/F5,0) -> 0.0200393 | G38: =IFERROR(-G8/G5,0) -> 0.014591976 | H38: =IFERROR(-H8/H5,0) -> 0.015701799 | I38: =IFERROR(-I8/I5,0) -> 0.03816157 | ... O38: =IFERROR(-O8/O5,0) -> 0.017382353
A39: Promo rate % | B39: =IFERROR(-B7/B5,0) -> 0.036490596 | C39: =IFERROR(-C7/C5,0) -> 0.012019115 | D39: =IFERROR(-D7/D5,0) -> 0.032010118 | E39: =IFERROR(-E7/E5,0) -> 0.012266425 | F39: =IFERROR(-F7/F5,0) -> 0.0084306576 | G39: =IFERROR(-G7/G5,0) -> 0.0094614703 | H39: =IFERROR(-H7/H5,0) -> 0.013810216 | I39: =IFERROR(-I7/I5,0) -> 0.011866774 | ... O39: =IFERROR(-O7/O5,0) -> 0.014963878
A40: Amazon fee % (incl VAT) of net sales | B40: =IFERROR(-B20/B9,0) -> 0.43202067 | C40: =IFERROR(-C20/C9,0) -> 0.37766699 | D40: =IFERROR(-D20/D9,0) -> 0.34135288 | E40: =IFERROR(-E20/E9,0) -> 0.3799151 | F40: =IFERROR(-F20/F9,0) -> 0.33778251 | G40: =IFERROR(-G20/G9,0) -> 0.38532842 | H40: =IFERROR(-H20/H9,0) -> 0.37787666 | I40: =IFERROR(-I20/I9,0) -> 0.32518922 | ... O40: =IFERROR(-O20/O9,0) -> 0.38910041
A41: Net margin % | B41: =IFERROR(B34/B9,0) -> 0.12085402 | C41: =IFERROR(C34/C9,0) -> 0.28781624 | D41: =IFERROR(D34/D9,0) -> 0.10115641 | E41: =IFERROR(E34/E9,0) -> 0.13663147 | F41: =IFERROR(F34/F9,0) -> 0.22956123 | G41: =IFERROR(G34/G9,0) -> 0.22884468 | H41: =IFERROR(H34/H9,0) -> 0.28801069 | I41: =IFERROR(I34/I9,0) -> 0.18112202 | ... O41: =IFERROR(O34/O9,0) -> 0.18018944
A43: ASSUMPTIONS & NOTES
A44: COGS = DDP + import VAT. Fees & PPC shown incl VAT — none reclaimable while unregistered.
A45: Blended landed £/unit (computed) | B45: =IFERROR(-O32/O30,0) -> 3.2095049
...

Sheet SKU Concentration
B2: SKU CONCENTRATION — trailing 12 months (product sales, orders)
B4: SKU | C4: TTM Sales | D4: % of total | E4: Product family
B5: Black Fidget Pen | C5: 22425.87 | D5: =C5/$C$21 -> 0.20990942 | E5: Fidget Pen
B6: 15k-pink-loom | C6: 18527.38 | D6: =C6/$C$21 -> 0.17341898 | E6: Loom Bands
B7: MSB-001 | C7: 12441.93 | D7: =C7/$C$21 -> 0.11645828 | E7: Other
B8: 15k-loom-purple | C8: 10498.51 | D8: =C8/$C$21 -> 0.098267587 | E8: Loom Bands
B9: 15k loom blue | C9: 10030.43 | D9: =C9/$C$21 -> 0.09388629 | E9: Loom Bands
B10: Purple Fidget Pen | C10: 8104.53 | D10: =C10/$C$21 -> 0.075859584 | E10: Fidget Pen
B11: 15k-loom-white | C11: 4715.08 | D11: =C11/$C$21 -> 0.044133837 | E11: Loom Bands
B12: Golden Fidget Pen | C12: 3525.22 | D12: =C12/$C$21 -> 0.032996574 | E12: Fidget Pen
B13: YC-H5RX-YASA | C13: 3413.11 | D13: =C13/$C$21 -> 0.031947208 | E13: Other
B14: Blue Fidget Pen | C14: 2972.46 | D14: =C14/$C$21 -> 0.02782266 | E14: Fidget Pen
B15: glow loom | C15: 2692.13 | D15: =C15/$C$21 -> 0.02519873 | E15: Loom Bands
B16: multi refills | C16: 2561.34 | D16: =C16/$C$21 -> 0.023974516 | E16: Loom Bands
... B20: Other small SKUs (7) | C20: 288.5 | D20: =C20/$C$21 -> 0.0027004021 | E20: Mixed
B21: TOTAL | C21: =SUM(C5:C20) -> 106835.94 | D21: =C21/C21 -> 1
B23: By product family
B24: Family | C24: TTM Sales | D24: % of total
B25: Loom Bands | C25: 50750.85 | D25: =C25/$C$21 -> 0.47503537
B26: Fidget Pen | C26: 37201.92 | D26: =C26/$C$21 -> 0.3482154
B27: Other | C27: 18883.17 | D27: =C27/$C$21 -> 0.17674923
B29: Concentration
B30: Distinct SKUs | C30: 22
B31: Top SKU % | C31: =C5/C21 -> 0.20990942
B32: Top 3 SKUs % | C32: =SUM(C5:C7)/C21 -> 0.49978668
B33: Top 5 SKUs % | C33: =SUM(C5:C9)/C21 -> 0.69194056
B35: Note: 22 SKUs but ~3 product families; a large share sits in Loom Bands + Fidget Pens. Variation SKUs (colours/refills) of the same product share supply-chain and demand risk.

Sheet COGS Build
A1: COGS BUILD — actual units per SKU × per-SKU landed cost (from seller's evaluation)
A2: Net units (orders − refunds) per SKU per month. £/unit is driven by the editable COST RATE TABLE (right). Monthly COGS = Σ(units × cost). TTM = Jul-25 to Jun-26.
A3: SKU | B3: £/unit | C3: Jun-25 | D3: Jul-25 | E3: Aug-25 | F3: Sep-25 | G3: Oct-25 | H3: Nov-25 | I3: Dec-25 | J3: Jan-26 | K3: Feb-26 | L3: Mar-26 | M3: Apr-26 | N3: May-26 | O3: Jun-26 | P3: TTM units | Q3: TTM COGS | R3: Family | S3: COST RATE TABLE (edit)
S4: Loom kit | T4: 6.61
A5: 15k-pink-loom | B5: =$T$4 -> 6.61 | C5: 186 | D5: 75 | E5: 65 | F5: 81 | G5: 49 | H5: 156 | I5: 151 | J5: 43 | K5: 60 | L5: 49 | M5: 62 | N5: 51 | O5: 53 | P5: =SUM(D5:O5) -> 895 | Q5: =P5*B5 -> 5915.95 | R5: Loom kit | S5: Fidget pen | T5: 2.48
A6: Black Fidget Pen | B6: =$T$5 -> 2.48 | C6: 80 | D6: 138 | E6: 113 | F6: 214 | G6: 165 | H6: 375 | I6: 517 | J6: 151 | K6: 47 | L6: 126 | M6: 35 | N6: 17 | O6: 53 | P6: =SUM(D6:O6) -> 1951 | Q6: =P6*B6 -> 4838.48 | R6: Fidget pen | S6: Refill/Glow | T6: 0.23
A7: 15k loom blue | B7: =$T$4 -> 6.61 | C7: 67 | D7: 0 | E7: 0 | F7: 50 | G7: 23 | H7: 55 | I7: 34 | J7: 10 | K7: 33 | L7: 75 | M7: 125 | N7: 98 | O7: 22 | P7: =SUM(D7:O7) -> 525 | Q7: =P7*B7 -> 3470.25 | R7: Loom kit | S7: MSB-001 | T7: 3.49
A8: 15k-loom-purple | B8: =$T$4 -> 6.61 | C8: 51 | D8: 77 | E8: 0 | F8: 20 | G8: 25 | H8: 56 | I8: 77 | J8: 25 | K8: 30 | L8: 30 | M8: 49 | N8: 71 | O8: 57 | P8: =SUM(D8:O8) -> 517 | Q8: =P8*B8 -> 3417.37 | R8: Loom kit | S8: MS-002 | T8: 3.3
A9: MSB-001 | B9: =$T$7 -> 3.49 | C9: 0 | D9: 0 | E9: 39 | F9: 129 | G9: 88 | H9: 8 | I9: 181 | J9: 26 | K9: 14 | L9: 77 | M9: 43 | N9: 14 | O9: 34 | P9: =SUM(D9:O9) -> 653 | Q9: =P9*B9 -> 2278.97 | R9: MSB-001 | S9: D0-8XWZ-Y0C6 | T9: 1.88
A10: Purple Fidget Pen | B10: =$T$5 -> 2.48 | C10: 30 | D10: 63 | E10: 42 | F10: 62 | G10: 98 | H10: 165 | I10: 46 | J10: 73 | K10: 82 | L10: 47 | M10: 39 | N10: 16 | O10: 59 | P10: =SUM(D10:O10) -> 792 | Q10: =P10*B10 -> 1964.16 | R10: Fidget pen | S10: YC-H5RX-YASA | T10: 3.2
A11: 15k-loom-white | B11: =$T$4 -> 6.61 | C11: 1 | D11: 95 | E11: 1 | F11: 3 | G11: 5 | H11: 19 | I11: 51 | J11: 11 | K11: 33 | L11: 36 | M11: 35 | N11: 0 | O11: 0 | P11: =SUM(D11:O11) -> 289 | Q11: =P11*B11 -> 1910.29 | R11: Loom kit
A12: YC-H5RX-YASA | B12: =$T$10 -> 3.2 | C12: 0 | D12: 0 | E12: 84 | F12: 32 | G12: 8 | H12: 32 | I12: 54 | J12: 113 | K12: 16 | L12: 0 | M12: 0 | N12: 0 | O12: 0 | P12: =SUM(D12:O12) -> 339 | Q12: =P12*B12 -> 1084.8 | R12: YC-H5RX-YASA | S12: Yellow = editable. Change a rate and every SKU in that family, the monthly COGS, and the P&L all update.
A13: Golden Fidget Pen | B13: =$T$5 -> 2.48 | C13: 0 | D13: 4 | E13: 13 | F13: 14 | G13: 21 | H13: 33 | I13: 122 | J13: 29 | K13: 15 | L13: 14 | M13: 5 | N13: 1 | O13: 4 | P13: =SUM(D13:O13) -> 275 | Q13: =P13*B13 -> 682 | R13: Fidget pen
A14: Blue Fidget Pen | B14: =$T$5 -> 2.48 | C14: 0 | D14: 0 | E14: 0 | F14: 0 | G14: 0 | H14: 48 | I14: 100 | J14: 0 | K14: 6 | L14: 29 | M14: 5 | N14: 17 | O14: 31 | P14: =SUM(D14:O14) -> 236 | Q14: =P14*B14 -> 585.28 | R14: Fidget pen
A15: D0-8XWZ-Y0C6 | B15: =$T$9 -> 1.88 | C15: 0 | D15: 31 | E15: 31 | F15: 36 | G15: 58 | H15: 39 | I15: 0 | J15: 0 | K15: 0 | L15: 0 | M15: 0 | N15: 0 | O15: 0 | P15: =SUM(D15:O15) -> 195 | Q15: =P15*B15 -> 366.6 | R15: D0-8XWZ-Y0C6
A16: MS-002 | B16: =$T$8 -> 3.3 | C16: 0 | D16: 0 | E16: 3 | F16: 25 | G16: 18 | H16: 45 | I16: 5 | J16: 0 | K16: 0 | L16: 0 | M16: 0 | N16: 0 | O16: 0 | P16: =SUM(D16:O16) -> 96 | Q16: =P16*B16 -> 316.8 | R16: MS-002
A17: glow loom | B17: =$T$6 -> 0.23 | C17: 44 | D17: 53 | E17: 1 | F17: 48 | G17: 118 | H17: 70 | I17: 70 | J17: 57 | K17: 56 | L17: 23 | M17: 7 | N17: 91 | O17: 85 | P17: =SUM(D17:O17) -> 679 | Q17: =P17*B17 -> 156.17 | R17: Refill/Glow
A18: multi refills | B18: =$T$6 -> 0.23 | C18: 15 | D18: 74 | E18: 102 | F18: 14 | G18: 27 | H18: 8 | I18: 15 | J18: 24 | K18: 26 | L18: 51 | M18: 34 | N18: 76 | O18: 184 | P18: =SUM(D18:O18) -> 635 | Q18: =P18*B18 -> 146.05 | R18: Refill/Glow
A19: black refills | B19: =$T$6 -> 0.23 | C19: 3 | D19: 60 | E19: 103 | F19: 48 | G19: 31 | H19: 28 | I19: 56 | J19: 18 | K19: 18 | L19: 14 | M19: 1 | N19: 9 | O19: 8 | P19: =SUM(D19:O19) -> 394 | Q19: =P19*B19 -> 90.62 | R19: Refill/Glow
A20: White loom kit FBM | B20: =$T$4 -> 6.61 | C20: 0 | D20: 0 | E20: 0 | F20: 0 | G20: 0 | H20: 0 | I20: 0 | J20: 0 | K20: 0 | L20: 0 | M20: 0 | N20: 1 | O20: 3 | P20: =SUM(D20:O20) -> 4 | Q20: =P20*B20 -> 26.44 | R20: Loom kit
A21: Multi Function Tool Pen | B21: =$T$5 -> 2.48 | C21: 0 | D21: 0 | E21: 0 | F21: 0 | G21: 0 | H21: 0 | I21: 0 | J21: 0 | K21: 0 | L21: 0 | M21: 0 | N21: 0 | O21: 5 | P21: =SUM(D21:O21) -> 5 | Q21: =P21*B21 -> 12.4 | R21: Fidget pen
A22: Putty Fidget Toy FBM | B22: =$T$5 -> 2.48 | C22: 0 | D22: 0 | E22: 0 | F22: 0 | G22: 6 | H22: -1 | I22: 0 | J22: 0 | K22: 0 | L22: 0 | M22: 0 | N22: 0 | O22: 0 | P22: =SUM(D22:O22) -> 5 | Q22: =P22*B22 -> 12.4 | R22: Fidget pen
A23: Silver Fidget Pen | B23: =$T$5 -> 2.48 | C23: 0 | D23: 0 | E23: 0 | F23: 0 | G23: 0 | H23: 0 | I23: 0 | J23: 0 | K23: 0 | L23: 0 | M23: 0 | N23: 2 | O23: 1 | P23: =SUM(D23:O23) -> 3 | Q23: =P23*B23 -> 7.44 | R23: Fidget pen
A24: Black Fidget Pen FBM | B24: =$T$5 -> 2.48 | C24: 0 | D24: 2 | E24: 0 | F24: 0 | G24: 0 | H24: 0 | I24: 0 | J24: 0 | K24: 0 | L24: 0 | M24: 0 | N24: 0 | O24: 0 | P24: =SUM(D24:O24) -> 2 | Q24: =P24*B24 -> 4.96 | R24: Fidget pen
A25: GD-MC-B Refill | B25: =$T$6 -> 0.23 | C25: 0 | D25: 0 | E25: 0 | F25: 0 | G25: 0 | H25: 0 | I25: 0 | J25: 0 | K25: 0 | L25: 0 | M25: 0 | N25: 0 | O25: 7 | P25: =SUM(D25:O25) -> 7 | Q25: =P25*B25 -> 1.61 | R25: Refill/Glow
A26: MD-GIN-FBM | B26: =$T$6 -> 0.23 | C26: 0 | D26: 0 | E26: 0 | F26: 0 | G26: 0 | H26: 0 | I26: 0 | J26: 0 | K26: 0 | L26: 0 | M26: 0 | N26: 0 | O26: 6 | P26: =SUM(D26:O26) -> 6 | Q26: =P26*B26 -> 1.38 | R26: Refill/Glow
A27: Monthly COGS (bottom-up) | B27: =IFERROR(Q27/P27,0) -> 3.2095049 | C27: =SUMPRODUCT($B$5:$B$26,C5:C26) -> 2303.11 | D27: =SUMPRODUCT($B$5:$B$26,D5:D26) -> 2247.32 | E27: =SUMPRODUCT($B$5:$B$26,E5:E26) -> 1373.37 | F27: =SUMPRODUCT($B$5:$B$26,F5:F26) -> 2465.23 | G27: =SUMPRODUCT($B$5:$B$26,G5:G26) -> 1935.06 | H27: =SUMPRODUCT($B$5:$B$26,H5:H26) -> 3804.58 | I27: =SUMPRODUCT($B$5:$B$26,I5:I26) -> 4869.15 | J27: =SUMPRODUCT($B$5:$B$26,J5:J26) -> 1690.84 | ... O27: =SUMPRODUCT($B$5:$B$26,O5:O26) -> 1457.15 | P27: =SUM(P5:P26) -> 8503 | Q27: =SUM(Q5:Q26) -> 27290.42
A29: Blended landed cost per unit — reconciliation
A30: This model (bottom-up, TTM) | B30: =IFERROR(Q27/P27,0) -> 3.2095049
A31: Seller's evaluation P&L (implied) | B31: 3.35
A32: Seller's stated 'higher end' | B32: 6.5
A34: → The bottom-up blend (~£3.30) matches the seller's own implied £3.35, NOT the £6.50 headline. The £6.50 is essentially the loom-kit cost; the sales mix (many £2.48 pens & £0.23 refills) pulls the average down.

Sheet PPC Invoices
B2: PPC INVOICES — 42 Amazon advertising tax invoices
B3: VAT = gross − net (every invoice = net × 1.20). Bucketed by invoice date. Compared to the 'Cost of Advertising' in the settlement PDFs.
B5: Monthly summary (bucketed by invoice date)
B6: Month | C6: # inv | D6: PPC net | E6: PPC VAT | F6: PPC gross | G6: Settlement | H6: Diff
B7: Jun-25 | C7: 3 | D7: 1038.02 | E7: 207.61 | F7: =D7+E7 -> 1245.63 | G7: 609.12 | H7: =F7-G7 -> 636.51
B8: Jul-25 | C8: 2 | D8: 679.76 | E8: 135.96 | F8: =D8+E8 -> 815.72 | G8: 207.16 | H8: =F8-G8 -> 608.56
B9: Aug-25 | C9: 4 | D9: 1596.6 | E9: 319.32 | F9: =D9+E9 -> 1915.92 | G9: 1915.92 | H9: =F9-G9 -> 0
B10: Sep-25 | C10: 5 | D10: 1731.41 | E10: 346.28 | F10: =D10+E10 -> 2077.69 | G10: 2077.69 | H10: =F10-G10 -> 0
B11: Oct-25 | C11: 3 | D11: 1302.08 | E11: 260.41 | F11: =D11+E11 -> 1562.49 | G11: 1562.49 | H11: =F11-G11 -> 0
B12: Nov-25 | C12: 3 | D12: 1370.32 | E12: 274.06 | F12: =D12+E12 -> 1644.38 | G12: 1644.38 | H12: =F12-G12 -> 0
B13: Dec-25 | C13: 5 | D13: 2104.05 | E13: 420.81 | F13: =D13+E13 -> 2524.86 | G13: 2524.86 | H13: =F13-G13 -> 0
B14: Jan-26 | C14: 3 | D14: 1410.94 | E14: 282.18 | F14: =D14+E14 -> 1693.12 | G14: 1693.12 | H14: =F14-G14 -> 0
B15: Feb-26 | C15: 2 | D15: 701.01 | E15: 140.2 | F15: =D15+E15 -> 841.21 | G15: 841.21 | H15: =F15-G15 -> 0
B16: Mar-26 | C16: 3 | D16: 1448.54 | E16: 289.72 | F16: =D16+E16 -> 1738.26 | G16: 1738.26 | H16: =F16-G16 -> 0
B17: Apr-26 | C17: 3 | D17: 1316.6 | E17: 263.32 | F17: =D17+E17 -> 1579.92 | G17: 1579.92 | H17: =F17-G17 -> 0
B18: May-26 | C18: 2 | D18: 613.48 | E18: 122.7 | F18: =D18+E18 -> 736.18 | G18: 1336.44 | H18: =F18-G18 -> -600.26
B19: Jun-26 | C19: 3 | D19: 1283.71 | E19: 256.74 | F19: =D19+E19 -> 1540.45 | G19: 1540.45 | H19: =F19-G19 -> 0
B20: TOTAL | C20: =SUM(C7:C19) -> 41 | D20: =SUM(D7:D19) -> 16596.52 | E20: =SUM(E7:E19) -> 3319.31 | F20: =SUM(F7:F19) -> 19915.83 | G20: =SUM(G7:G19) -> 19271.02 | H20: =F20-G20 -> 644.81
B22: Reconciliation: 10 of 13 months match the settlement advertising to the penny. Jun-25 & Jul-25 (ramp-up) and May-26 differ only by billing-cycle timing at month boundaries. One invoice (13-May-2025, £246.35) predates the window. The P&L uses the settlement monthly figure split at the invoice-confirmed 20%, so it reconciles exactly.
B26: All 42 invoices
B27: Invoice # | C27: Date | D27: Period | E27: Net | F27: VAT | G27: Gross
B28: 1485452M7PA25 | C28: 13-05-2025 | D28: 08-05-2025 - 13-05-2025 | E28: 205.29 | F28: 41.06 | G28: 246.35
B29: 1708804M7PA25 | C29: 02-06-2025 | D29: 13-05-2025 - 02-06-2025 | E29: 174.24 | F29: 34.85 | G29: 209.09
B30: 1813133M7PA25 | C30: 10-06-2025 | D30: 02-06-2025 - 10-06-2025 | E30: 356.18 | F30: 71.24 | G30: 427.42
B31: 1991397M7PA25 | C31: 29-06-2025 | D31: 10-06-2025 - 29-06-2025 | E31: 507.6 | F31: 101.52 | G31: 609.12
B32: 2035516M7PA25 | C32: 02-07-2025 | D32: 29-06-2025 - 02-07-2025 | E32: 172.63 | F32: 34.53 | G32: 207.16
B33: 2257833M7PA25 | C33: 16-07-2025 | D33: 02-07-2025 - 16-07-2025 | E33: 507.13 | F33: 101.43 | G33: 608.56
B34: 2464827M7PA25 | C34: 02-08-2025 | D34: 16-07-2025 - 02-08-2025 | E34: 406.52 | F34: 81.3 | G34: 487.82
B35: 2621419M7PA25 | C35: 15-08-2025 | D35: 02-08-2025 - 15-08-2025 | E35: 509.23 | F35: 101.85 | G35: 611.08
B36: 2702972M7PA25 | C36: 24-08-2025 | D36: 15-08-2025 - 24-08-2025 | E36: 509.49 | F36: 101.9 | G36: 611.39
B37: 2741531M7PA25 | C37: 28-08-2025 | D37: 24-08-2025 - 28-08-2025 | E37: 171.36 | F37: 34.27 | G37: 205.63
B38: 2792922M7PA25 | C38: 01-09-2025 | D38: 28-08-2025 - 01-09-2025 | E38: 152.02 | F38: 30.4 | G38: 182.42
B39: 2926762M7PA25 | C39: 07-09-2025 | D39: 01-09-2025 - 07-09-2025 | E39: 203.79 | F39: 40.76 | G39: 244.55
... B69: 2608540M7PA26 | C69: 26-06-2026 | D69: 12-06-2026 - 26-06-2026 | E69: 500.02 | F69: 100 | G69: 600.02
B70: TOTAL | E70: =SUM(E28:E69) -> 16801.81 | F70: =SUM(F28:F69) -> 3360.37 | G70: =SUM(G28:G69) -> 20162.18

Sheet Fee Reconciliation
B2: FEE RECONCILIATION — Summary PDF vs detailed Transaction CSV
B3: Confirms each Amazon fee in the P&L comes from the Payment report and ties out both ways. Costs negative. 'd' = CSV − Summary (≈0 = tie).
C5: Referral (selling fee) | F5: FBA fulfilment | I5: Storage & inbound
B6: Month | C6: Summary | D6: CSV | E6: d | F6: Summary | G6: CSV | H6: d | I6: Summary | J6: CSV | K6: d
B7: Jun-25 | C7: -788.05 | D7: -788.05 | E7: =D7-C7 -> 0 | F7: -1679.97 | G7: -1679.97 | H7: =G7-F7 -> 0 | I7: -169.72 | J7: -169.72 | K7: =J7-I7 -> 0
B8: Jul-25 | C8: -509.44 | D8: -509.44 | E8: =D8-C8 -> 0 | F8: -2047.58 | G8: -2047.58 | H8: =G8-F8 -> 0 | I8: -101.55 | J8: -101.55 | K8: =J8-I8 -> 0
B9: Aug-25 | C9: -130.33 | D9: -130.33 | E9: =D9-C9 -> 0 | F9: -1663.48 | G9: -1663.48 | H9: =G9-F9 -> 0 | I9: -158.52 | J9: -158.52 | K9: =J9-I9 -> 0
B10: Sep-25 | C10: -985.54 | D10: -985.54 | E10: =D10-C10 -> 0 | F10: -2393.87 | G10: -2393.87 | H10: =G10-F10 -> 0 | I10: -88.89 | J10: -88.89 | K10: =J10-I10 -> 0
B11: Oct-25 | C11: -301.86 | D11: -301.86 | E11: =D11-C11 -> 0 | F11: -2067.71 | G11: -2067.71 | H11: =G11-F11 -> 0 | I11: -156.98 | J11: -156.98 | K11: =J11-I11 -> 0
B12: Nov-25 | C12: -1626.52 | D12: -1626.47 | E12: =D12-C12 -> 0.05 | F12: -3464.75 | G12: -3464.75 | H12: =G12-F12 -> 0 | I12: -200.53 | J12: -200.53 | K12: =J12-I12 -> 0
B13: Dec-25 | C13: -3110.65 | D13: -3110.65 | E13: =D13-C13 -> 0 | F13: -4676.72 | G13: -4676.72 | H13: =G13-F13 -> 0 | I13: -434.77 | J13: -434.77 | K13: =J13-I13 -> 0
B14: Jan-26 | C14: 0 | D14: 0 | E14: =D14-C14 -> 0 | F14: -1790.18 | G14: -1790.18 | H14: =G14-F14 -> 0 | I14: -401.56 | J14: -401.56 | K14: =J14-I14 -> 0
B15: Feb-26 | C15: -133.62 | D15: -133.62 | E15: =D15-C15 -> 0 | F15: -1378.62 | G15: -1378.62 | H15: =G15-F15 -> 0 | I15: -290.96 | J15: -290.96 | K15: =J15-I15 -> 0
B16: Mar-26 | C16: -1141.76 | D16: -1141.76 | E16: =D16-C16 -> 0 | F16: -1858.51 | G16: -1858.51 | H16: =G16-F16 -> 0 | I16: -265.61 | J16: -265.61 | K16: =J16-I16 -> 0
B17: Apr-26 | C17: -1048.71 | D17: -1048.71 | E17: =D17-C17 -> 0 | F17: -1660.77 | G17: -1660.77 | H17: =G17-F17 -> 0 | I17: -237.77 | J17: -237.77 | K17: =J17-I17 -> 0
B18: May-26 | C18: -1121.06 | D18: -1121.06 | E18: =D18-C18 -> 0 | F18: -1722.91 | G18: -1722.91 | H18: =G18-F18 -> 0 | I18: -41.8 | J18: -41.8 | K18: =J18-I18 -> 0
B19: Jun-26 | C19: -905.47 | D19: -905.47 | E19: =D19-C19 -> 0 | F19: -1770.09 | G19: -1770.09 | H19: =G19-F19 -> 0 | I19: 0 | J19: 0 | K19: =J19-I19 -> 0
B20: TOTAL | C20: =SUM(C7:C19) -> -11803.01 | D20: =SUM(D7:D19) -> -11802.96 | E20: =D20-C20 -> 0.05 | F20: =SUM(F7:F19) -> -28175.16 | G20: =SUM(G7:G19) -> -28175.16 | H20: =G20-F20 -> 0 | I20: =SUM(I7:I19) -> -2548.66 | J20: =SUM(J7:J19) -> -2548.66 | K20: =J20-I20 -> 0
B21: Referral, FBA fulfilment and storage each tie to the transaction CSV to the penny. (Referral shown as order-line selling fees; the summary's small 'selling fee refunds' credit is a separate line in the P&L.)
B24: OTHER FEES — full composition (Service fee split into Subscription / Deal / Coupon)
B25: Every component from the Payment report. Subscription = £30/mo seller plan; Deal fees = Lightning/Best-Deal participation + performance charges; Coupon = one-off coupon redemption. Columns sum to the P&L 'Other Fees' line and tie to the transaction CSV to the penny.
B27: Month | C27: Other txn fees | D27: Other txn refunds | E27: Subscription | F27: Deal fees | G27: Coupon fees | H27: Refund admin | I27: Delivery labels | J27: Adjustments | K27: Total Other
B28: Jun-25 | C28: -50.45 | D28: 0.12 | E28: -30 | F28: -60 | G28: -39.96 | H28: -1.04 | I28: 0 | J28: 0 | K28: =SUM(C28:J28) -> -181.33
B29: Jul-25 | C29: -50.05 | D29: 0.14 | E29: -30 | F29: -34.67 | G29: 0 | H29: -0.52 | I29: 0 | J29: 0 | K29: =SUM(C29:J29) -> -115.1
B30: Aug-25 | C30: -34.96 | D30: 0.08 | E30: -30 | F30: 0 | G30: 0 | H30: -0.79 | I30: 0 | J30: 0 | K30: =SUM(C30:J30) -> -65.67
B31: Sep-25 | C31: -66.08 | D31: 0.18 | E31: -30 | F31: -10.07 | G31: 0 | H31: -1.07 | I31: 0 | J31: 0 | K31: =SUM(C31:J31) -> -107.04
B32: Oct-25 | C32: -45.97 | D32: 0.16 | E32: -30 | F32: -109.19 | G32: 0 | H32: -0.96 | I32: -9.55 | J32: -13.33 | K32: =SUM(C32:J32) -> -208.84
B33: Nov-25 | C33: -100.48 | D33: 0.55 | E33: -30 | F33: -34.57 | G33: 0 | H33: -4.42 | I33: -3.28 | J33: 0 | K33: =SUM(C33:J33) -> -172.2
B34: Dec-25 | C34: -153.9 | D34: 1.15 | E34: -30 | F34: 0 | G34: 0 | H34: -10.92 | I34: 0 | J34: -1.13 | K34: =SUM(C34:J34) -> -194.8
B35: Jan-26 | C35: -34.29 | D35: 0.68 | E35: -30 | F35: 0 | G35: 0 | H35: -6.59 | I35: 0 | J35: 0 | K35: =SUM(C35:J35) -> -70.2
B36: Feb-26 | C36: -29.83 | D36: 0.06 | E36: -30 | F36: -83.22 | G36: 0 | H36: -0.47 | I36: 0 | J36: -6.91 | K36: =SUM(C36:J36) -> -150.37
B37: Mar-26 | C37: -59.51 | D37: 0.57 | E37: -30 | F37: -140.15 | G37: 0 | H37: -5.7 | I37: 0 | J37: 0 | K37: =SUM(C37:J37) -> -234.79
B38: Apr-26 | C38: -54.09 | D38: 0.56 | E38: -30 | F38: -118.92 | G38: 0 | H38: -3.95 | I38: 0 | J38: 0 | K38: =SUM(C38:J38) -> -206.4
B39: May-26 | C39: -53.76 | D39: 0.27 | E39: -30 | F39: -75.46 | G39: 0 | H39: -1.22 | I39: 0 | J39: 0 | K39: =SUM(C39:J39) -> -160.17
B40: Jun-26 | C40: -51.84 | D40: 0.2 | E40: -30 | F40: -31.7 | G40: 0 | H40: -1.84 | I40: -15.36 | J40: 0 | K40: =SUM(C40:J40) -> -130.54
B41: TOTAL | C41: =SUM(C28:C40) -> -785.21 | D41: =SUM(D28:D40) -> 4.72 | E41: =SUM(E28:E40) -> -390 | F41: =SUM(F28:F40) -> -697.95 | G41: =SUM(G28:G40) -> -39.96 | H41: =SUM(H28:H40) -> -39.49 | I41: =SUM(I28:I40) -> -28.19 | J41: =SUM(J28:J40) -> -21.37 | K41: =SUM(K28:K40) -> -1997.45

Sheet Summary
B2: SUMMARY — trailing 12 months (Jul-25 to Jun-26)
B4: Reliable (straight from the data) | E4: Bottom line (business NOT VAT-registered)
B5: Net Sales (TTM) | C5: ='P&L (from PDFs)'!O9 -> 106689.66 | E5: Net Sales (TTM) | F5: ='P&L (from PDFs)'!O9 -> 106689.66
B6: Units sold (net, TTM) | C6: ='P&L (from PDFs)'!O30 -> 8503 | E6: Total Amazon Fees incl VAT | F6: ='P&L (from PDFs)'!O20 -> -41512.99
B7: Avg selling price | C7: ='P&L (from PDFs)'!O31 -> 12.5645 | E7: PPC incl VAT | F7: ='P&L (from PDFs)'!O25 -> -18661.9
B8: Total Amazon Fees incl VAT (TTM) | C8: ='P&L (from PDFs)'!O20 -> -41512.99 | E8: COGS (DDP + import VAT) | F8: ='P&L (from PDFs)'!O32 -> -27290.42
B9: PPC / Advertising incl VAT (TTM) | C9: ='P&L (from PDFs)'!O25 -> -18661.9 | E9: Output VAT (not registered) | F9: ='P&L (from PDFs)'!O33 -> 0
B10: COGS (TTM, bottom-up) | C10: ='P&L (from PDFs)'!O32 -> -27290.42 | E10: NET PROFIT (TTM) | F10: ='P&L (from PDFs)'!O34 -> 19224.35
B11: TACoS % | C11: ='P&L (from PDFs)'!O37 -> 0.17491761 | E11: Net margin % | F11: ='P&L (from PDFs)'!O41 -> 0.18018944
B12: Refund rate % | C12: ='P&L (from PDFs)'!O38 -> 0.017382353 | E12: Blended landed £/unit | F12: ='P&L (from PDFs)'!B45 -> 3.2095049
B13: Avg monthly net sales | C13: ='P&L (from PDFs)'!P9 -> 8890.805
B15: Sensitivity — NET PROFIT (TTM) | E15: Year-on-year (Jun)
B16: rows = landed £/unit · cols = VAT status · PPC included, no OpEx | E16: Jun-25 net sales | F16: ='P&L (from PDFs)'!B9 -> 6513.23
B17: Landed \ VAT | C17: Not registered | D17: If registered* | E17: Jun-26 net sales | F17: ='P&L (from PDFs)'!N9 -> 6143.81
B18: 3.3 | C18: ='P&L (from PDFs)'!O9+'P&L (from PDFs)'!O20+'P&L (from PDFs)'!O25-'P&L (from PDFs)'!O30*3.3 -> 18454.87 | D18: ='P&L (from PDFs)'!O9+'P&L (from PDFs)'!O20+'P&L (from PDFs)'!O25-'P&L (from PDFs)'!O30*3.3-'P&L (from PDFs)'!O9/6 -> 673.26 | E18: YoY change % | F18: =IFERROR((F17-F16)/F16,0) -> -0.056718402
B19: 4.5 | C19: ='P&L (from PDFs)'!O9+'P&L (from PDFs)'!O20+'P&L (from PDFs)'!O25-'P&L (from PDFs)'!O30*4.5 -> 8251.27 | D19: ='P&L (from PDFs)'!O9+'P&L (from PDFs)'!O20+'P&L (from PDFs)'!O25-'P&L (from PDFs)'!O30*4.5-'P&L (from PDFs)'!O9/6 -> -9530.34
B20: 6.5 | C20: ='P&L (from PDFs)'!O9+'P&L (from PDFs)'!O20+'P&L (from PDFs)'!O25-'P&L (from PDFs)'!O30*6.5 -> -8754.73 | D20: ='P&L (from PDFs)'!O9+'P&L (from PDFs)'!O20+'P&L (from PDFs)'!O25-'P&L (from PDFs)'!O30*6.5-'P&L (from PDFs)'!O9/6 -> -26536.34 | E20: Concentration
B21: *If registered: output VAT applies; some input VAT would be reclaimable (not modelled), so treat as a rough floor. | E21: Top SKU | F21: 0.21
E22: Top 5 SKUs | F22: 0.692
E23: Loom + Fidget families | F23: 0.823

Sheet Traffic & Conversion
A1: TRAFFIC & CONVERSION — from Business Reports (Detail Page Sales & Traffic)
A2: Blue = actual. Conversion = units ordered / sessions. Buy Box = session-weighted. TTM = Jul-25 to Jun-26.
A3: Metric | B3: Jun-25 | C3: Jul-25 | D3: Aug-25 | E3: Sep-25 | F3: Oct-25 | G3: Nov-25 | H3: Dec-25 | I3: Jan-26 | J3: Feb-26 | K3: Mar-26 | L3: Apr-26 | M3: May-26 | N3: Jun-26 | O3: TTM
A4: Active child ASINs | B4: 11 | C4: 16 | D4: 15 | E4: 19 | F4: 20 | G4: 19 | H4: 18 | I4: 17 | J4: 17 | K4: 17 | L4: 17 | M4: 19 | N4: 21 | O4: —
A5: Sessions | B5: 3770 | C5: 4227 | D5: 3558 | E5: 5194 | F5: 5165 | G5: 7152 | H5: 7518 | I5: 4195 | J5: 3189 | K5: 4011 | L5: 3612 | M5: 3803 | N5: 4429 | O5: =SUM(C5:N5) -> 56053
A6: Page views | B6: 5438 | C6: 6007 | D6: 4786 | E6: 6969 | F6: 6982 | G6: 9637 | H6: 10404 | I6: 5723 | J6: 4250 | K6: 5534 | L6: 4868 | M6: 5013 | N6: 5973 | O6: =SUM(C6:N6) -> 76146
A7: Units ordered | B7: 497 | C7: 672 | D7: 613 | E7: 788 | F7: 760 | G7: 1184 | H7: 1457 | I7: 604 | J7: 462 | K7: 573 | L7: 445 | M7: 471 | N7: 626 | O7: =SUM(C7:N7) -> 8655
A8: Conversion % (units / sessions) | B8: =IFERROR(B7/B5,0) -> 0.13183024 | C8: =IFERROR(C7/C5,0) -> 0.158978 | D8: =IFERROR(D7/D5,0) -> 0.1722878 | E8: =IFERROR(E7/E5,0) -> 0.15171352 | F8: =IFERROR(F7/F5,0) -> 0.14714424 | G8: =IFERROR(G7/G5,0) -> 0.1655481 | H8: =IFERROR(H7/H5,0) -> 0.19380154 | I8: =IFERROR(I7/I5,0) -> 0.14398093 | ... O8: =IFERROR(O7/O5,0) -> 0.15440744
A9: Buy Box % (session-weighted) | B9: 0.999 | C9: 0.996 | D9: 0.996 | E9: 0.992 | F9: 0.996 | G9: 0.993 | H9: 0.993 | I9: 0.993 | J9: 0.992 | K9: 0.989 | L9: 0.991 | M9: 0.985 | N9: 0.92 | O9: —
A11: Read-outs
A12: • Conversion is healthy (TTM ~15.4%); peaked in Dec-25 (seasonal) and has softened to ~12-14% in Apr-Jun 2026 — mild downtrend worth watching.
A13: • Buy Box sat at ~99% all year, then DROPPED to 92% in Jun-26 — investigate: possible hijacker, pricing/suppression, or stock issue. Ask the seller directly.
A14: • Active ASIN count drifts up to 21 by Jun-26, but sales stay concentrated in a few (see SKU tab).
A15: • Sessions have eased from the autumn/Q4 peak — partly seasonal; confirm it isn't a ranking or ad-spend pullback.
